Workbook

Sheet Copy of Kertas Kerja
A1: No | B1: Nama Layanan | C1: Tujuan dan Fungsi Layanan | D1: Dasar Hukum Layanan | E1: SOP / Proses Bisnis Layanan | F1: Referensi Layanan | G1: Target Layanan | H1: Data yang dimasukan | I1: Data yang dihasilkan | J1: Sifat Data | K1: Data Pribadi | L1: Interval update data yang dihasilkan | M1: Aplikasi Pendukung | N1: Pengembang | O1: Pemilik | P1: Platform | Q1: Alamat Aplikasi | R1: Kategori Akses | S1: Jenis Aplikasi | T1: Tahun Pembuatan | U1: Status Aplikasi | V1: Telah Terintegrasi | W1: Terintegrasi dengan Aplikasi | X1: Mekanisme Integrasi | Y1: Frekuensi Sinkronisasi | Z1: Bidang / Unit Kerja | AA1: OPD | AB1: Nama | AC1: No. HP | AD1: Email
A2: 1 | B2: 2 | C2: 3 | D2: 4 | E2: 5 | F2: 6 | G2: 7 | H2: 8 | I2: 9 | J2: 10 | K2: 11 | L2: 12 | M2: 13 | N2: 14 | O2: 15 | P2: 16 | Q2: 17 | R2: 18 | S2: 19 | T2: 20 | U2: 21 | V2: 22 | W2: 23 | X2: 24 | Y2: 25 | Z2: 26 | AA2: 27 | AB2: 28 | AC2: 29 | AD2: 30
A3: Panduan | B3: Isikan dengan nama layanan yang selenggarakan | C3: Isikan dengan tujuan dan fungsi diselenggarakan layanan | D3: Isikan dengan dasar hukum penyelenggaraan layanan (Isikan dengan peraturan tingkat daerah, jika tidak ada dapat mengacu ke peraturan tingkat pusat) | E3: isikan dengan link dokumen berbentuk pdf terkait SOP / Proses Bisnis layanan | F3: Isikan referensi layanan sesuai daftar (Isikan dengan referensi layanan yang mendekati, dapat dilihat pada sheet referensi) | G3: Isikan dengan penerima layanan | H3: Isikan dengan input data | I3: Isikan dengan output data | J3: Isikan dengan sifat data | K3: Apakah terdapat Data Pribadi yang digunakan ? | L3: Pemutakhiran data hasil dari proses layanan | M3: Masukan nama aplikasi pendukung layanan, jika tidak ada maka isikan dengan "Belum terdapat aplikasi" | N3: Isikan dengan pengembang aplikasi | O3: Isikan dengan pemilik aplikasi | P3: Isikan dengan platform aplikasi | Q3: Isikan dengan alamat akses aplikasi, jika berbasis mobile isikan dengan link download | R3: Isikan dengan metode akses aplikasi | S3: Isikan dengan jenis aplikasi, informasi untuk satu arah, transaksi untuk dua arah) | T3: Isikan dengan tahun pembuatan | U3: Isikan dengan status aplikasi | V3: Apakah aplikasi telah terintegrasi ? | W3: Terintegrasi dengan aplikasi ? (Isikan dengan nama aplikasi, jika tidak isikan Tidak Terintegrasi | X3: Bagaimana proses integrasi berlangsung ? | Y3: Berapa lama integrasi data/layanan mutakhirkan ? | Z3: Isikan dengan unit kerja pelaksana layanan | AA3: Isikan dengan OPD pelaksana layanan | AB3: Isikan dengan Nama PIC pelaksana layanan | AC3: Isikan dengan nomor kontak pelaksana layanan | AD3: Isikan dengan email pelaksana layanan
A4: Contoh | B4: Layanan Pengaduan Masyarakat | C4: Layanan Pengaduan Masyarakat (LPM) adalah wadah atau sistem yang disediakan oleh instansi pemerintah (atau lembaga publik lainnya) bagi masyarakat untuk menyampaikan keluhan, saran, masukan, aspirasi, hingga laporan atas dugaan penyimpangan atau maladministrasi dalam penyelenggaraan pemerintahan dan pelayanan publik. | D4: Undang-Undang Nomor 25 Tahun 2009 tentang Pelayanan Publik | E4: abcd.pdf | F4: PENINGKATAN KUALITAS PELAYANAN PUBLIK | G4: Masyarakat | H4: Data Pengguna, Data Adun | I4: Data Aduan Masyarakat | J4: Tertutup | K4: Terdapat | L4: Harian | M4: SP4N Lapor | N4: Pusat | O4: Pusat | P4: Website dan Mobile | Q4: https://lapor.go.id/ | R4: Secara Online | S4: Transaksi | T4: 2018 | U4: Aktif | V4: Tidak | W4: Tidak Terintegrasi | X4: Tidak Terintegrasi | Y4: Tidak Terintegrasi | Z4: Bidang Informasi Komunikasi Publik | AA4: Diskominfo | AB4: Rima Diani, S.Si.Kom | AC4: 123 | AD4: rima@bandungkab.go.id
A5: Contoh | B5: Layanan Call center 112 | C5: Layanan Nomor Panggilan Darurat 112 merupakan layanan yang dapat digunakan saat terjadi keadaan darurat dengan menghubungi nomor 112 (Bebas Pulsa) yang akan terhubung dengan Pusat Panggilan Darurat (Call Center 112) yang dibangun oleh pemerintah daerah | D5: Permenkominfo 10/2016 tentang Layanan Nomor Tunggal Panggilan Darurat dan Keputusan Dirjen PPI 112/2019 tentang Pedoman Teknis Penyediaan Layanan Nomor Panggilan Darurat 112. | E5: Belum Tersedia | F5: PENINGKATAN KUALITAS PELAYANAN PUBLIK | G5: Masyarakat | H5: Data Pelapor dan Kejadian | I5: Data Laporan Kedaruratan | J5: Terbuka | K5: Terdapat | L5: Harian | M5: Sakti112 | N5: Pihak Ke 3 | O5: Pihak Ke 3 (Lisensi) | P5: Website | Q5: https://kabbandungv2.sakti112.id/ | R5: Secara Online | S5: Informasi | T5: 2023 | U5: Aktif | V5: Ya | W5: Tersedia untuk di integrasi ke aplikasi lain dan sudah dicoba ke aplikasi APAR milik disdamkar | X5: API | Y5: Lainnya | Z5: Bidang Informasi Komunikasi Publik | AA5: Diskominfo | AB5: Gugun | AC5: 456 | AD5: gugun@bandungkab.go.id
A6: 1 | B6: Layanan Data | C6: Pengelolaan Data Statistik Sektoral untuk pemanfaatan data melalui Portal Satu Data | D6: Perbup Simasda | F6: PENGELOLAAN DATA STATISTIK | G6: Masyarakat | H6: Data Statistik Sektoral yang bersumber dari produsen data/OPD | I6: Daftar Data Hasil Kegiatan Statistik di OPD yang tersaji pada portal satu data | J6: Terbuka | K6: Tidak terdapat | L6: Tahunan | M6: Simasda dan Portal Satu Data | N6: Diskominfo | O6: Kab. Bandung | P6: Website | Q6: https://simasda.bandungkab.go.id/ dan https://satudata.bandungkab.go.id/ | R6: Secara Online | S6: Informasi | T6: 2019 | U6: Aktif | V6: Ya | W6: Open data Provinsi Jawa Barat dan Satu Data Indonesia | X6: API | Y6: Tahunan | Z6: Bidang Statistik | AA6: Diskominfo | AB6: Nyimas Ayu Kikie Zakiyah | AC6: 0813-2184-5099 | AD6: kikiezaki72@gmail.com
A7: 2 | B7: Layanan Pembangunan dan Pengembangan Aplikasi | C7: Bertujuan untuk menjadi fasilitator dalam membangun dan mengembangkan aplikasi dpada Perangkat Daerah | F7: PENATAKELOLAAN APLIKASI INFORMATIKA | G7: Instansi Pemerintah Lainnya | H7: Permohonan Pembangunan dan Pengembangan Aplikasi dari OPD
A8: 3 | B8: Layanan Akses dan Kualitas Informasi Publik Pemerintah Daerah | C8: Bertujuan untuk menghitung indeks Layanan Akses dan Kualitas Informasi Publik Pemerintah Daerah | F8: PENGELOLAAN INFORMASI PUBLIK | G8: Masyarakat
A9: 4 | B9: Layanan Penerbitan Tanda Tangan Elektronik | C9: Sebagai Fasilitator dalam pelayanan penerbitan tanda tangan elektronik | F9: MANAJEMEN KEAMANAN INFORMASI | G9: Pegawai
A10: 5
A11: 6
A12: 7
A13: 8
A14: 9
A15: 10
A16: 11
A17: 12
A18: 13
A19: 14
A20: 15
A21: 16
... A55: 50

Sheet Ref
A1: No | B1: Nama Layanan | C1: Tujuan dan Fungsi Layanan | D1: Dasar Hukum Layanan | E1: SOP / Proses Bisnis Layanan | F1: REFERENSI LAYANAN | G1: Target Layanan | H1: Data yang dimasukan | I1: Data yang dihasilkan | J1: Sifat Data | K1: Data Pribadi | L1: Interval update data yang dihasilkan | M1: Aplikasi Pendukung | N1: Pengembang | O1: Pemilik | P1: Platform | Q1: Alamat Aplikasi | R1: Kategori Akses | S1: Jenis Aplikasi | T1: Tahun Pembuatan | U1: Status Aplikasi | V1: Telah Terintegrasi | W1: Terintegrasi dengan Aplikasi | X1: Mekanisme Integrasi | Y1: Frekuensi Sinkronisasi | Z1: Bidang | AA1: OPD | AB1: Nama | AC1: No. HP | AD1: Email | AF1: JUMLAH LAYANAN | AG1: JUMLAH APLIKASI
E2: Tersedia | F2: STRATEGI PERTAHANAN | G2: Pelaku Bisnis | J2: Terbuka | K2: Terdapat | L2: Harian | N2: Pusat | O2: Pusat | P2: Website | R2: Secara Online | S2: Informasi | U2: Aktif | V2: Ya | X2: API | Y2: Realtime | AA2: Setda
E3: Tidak Tersedia | F3: PERENCANAAN PERTAHANAN | G3: Masyarakat | J3: Tertutup | K3: Tidak terdapat | L3: Mingguan | N3: Provinsi | O3: Provinsi | P3: Mobile | R3: Secara Offline | S3: Transaksi | U3: Non Aktif | V3: Tidak | X3: Web Service | Y3: Harian | AA3: Setwan
F4: POTENSI PERTAHANAN | G4: Pegawai | J4: Terbatas | L4: Bulanan | N4: Diskominfo | O4: Kab. Bandung | P4: Desktop | U4: Maintenance | X4: Database to Database | Y4: Mingguan | AA4: Inspektorat
F5: KEKUATAN PERTAHANAN | G5: Instansi Pemerintah Lainnya | J5: Rahasia | L5: Tahunan | N5: OPD | O5: Pihak Ke 3 (Lisensi) | P5: Website dan Mobile | X5: Manual | Y5: Bulanan | AA5: Disdik
F6: PENYELENGGARAAN HUBUNGAN LUAR NEGERI DAN POLITIK LUAR NEGERI | L6: Lainnya | N6: Pihak Ke 3 | X6: Tidak Terintegrasi | Y6: Tahunan | AA6: Dinkes
F7: HUKUM DAN PERJANJIAN INTERNASIONAL | Y7: Lainnya | AA7: DPUTR
F8: INFORMASI DAN DIPLOMASI PUBLIK | Y8: Tidak Terintegrasi | AA8: Disperkimtan
F9: PROTOKOL DAN KONSULER | AA9: Dinsos
F10: PELINDUNGAN WNI | AA10: Disnaker
F11: FASILITAS DIPLOMATIK | AA11: DP2KBP3A
F12: PENINGKATAN DAYA SAING DAN KEMANDIRIAN INDUSTRI | AA12: DLH
F13: PENGUATAN IMPLEMENTASI MAKING INDONESIA 4 | AA13: Disdukcapil
F14: PENINGKATAN KEMAMPUAN INDUSTRI BARANG DAN JASA SERTA INDUSTRI HALAL DALAM NEGERI | AA14: DPMD
F15: PERLUASAN PENGUASAAN PASAR INDUSTRI | AA15: Dishub
F16: PENGUATAN KEWIRAUSAHAAN DAN INDUSTRI KECIL DAN MENENGAH | AA16: Diskominfo
F17: PEMERATAAN PERSEBARAN INDUSTRI | AA17: DPMPTSP
F18: PENGELOLAAN INDUSTRI KREATIF | AA18: Dispora
F19: PENGUATAN DAN PENGEMBANGAN PERDAGANGAN DALAM NEGERI | AA19: Disperdagin
F20: PENGUATAN PERDAGANGAN LUAR NEGERI | AA20: Distan
... F33: PENGEMBANGAN KELEMBAGAAN PETANI | AA33: BPBD
F34: PENGELOLAAN STANDARDISASI DAN PENILAIAN KESESUAIAN KOMODITAS TANAMAN PANGAN DAN HORTIKULTURA
F35: PENGELOLAAN STANDARDISASI DAN PENILAIAN KESESUAIAN PASCA PANEN TANAMAN PANGAN DAN HORTIKULTURA
F36: PENGELOLAAN STANDARDISASI DAN PENILAIAN KESESUAIAN PRASARANA DAN SARANA TANAMAN PANGAN DAN HORTIKULTURA
F37: PENGELOLAAN REKOMENDASI KEBIJAKAN SOSIAL EKONOMI PEMBANGUNAN TANAMAN PANGAN DAN HORTIKULTURA
F38: PENGELOLAAN LAHAN PERTANIAN
F39: PENGELOLAAN PUPUK DAN PESTISIDA
F40: PENGELOLAAN IRIGASI PERTANIAN, KONSERVASI AIR DAN LINGKUNGAN HIDUP
F41: PENGELOLAAN ALAT DAN MESIN PERTANIAN
F42: PENGELOLAAN PEMBIAYAAN TANAMAN PANGAN DAN HORTIKULTURA
F43: PENGELOLAAN LAYANAN PERIZINAN BERUSAHA BIDANG PERTANIAN DAN PERLINDUNGAN VARIETAS TANAMAN
F44: KETERSEDIAN PANGAN
F45: STABILITAS PASOKAN DAN HARGA PANGAN
... F307: PENGELOLAAN PELAYANAN KESEHATAN

Sheet Kertas Kerja - All
A1: No | B1: Nama Layanan | C1: Pemilik Layanan | D1: Tujuan dan Fungsi Layanan | E1: Dasar Hukum Layanan | F1: SOP / Proses Bisnis Layanan | G1: Referensi Layanan | H1: Target Layanan | I1: Data yang dimasukan | J1: Data yang dihasilkan | K1: Sifat Data | L1: Data Pribadi | M1: Interval update data yang dihasilkan | N1: Aplikasi Pendukung | O1: Pengembang | P1: Pemilik | Q1: Platform | R1: Alamat Aplikasi | S1: Kategori Akses | T1: Jenis Aplikasi | U1: Tahun Pembuatan | V1: Status Aplikasi | W1: Telah Terintegrasi | X1: Terintegrasi dengan Aplikasi | Y1: Mekanisme Integrasi | Z1: Frekuensi Sinkronisasi | AA1: Bidang / Unit Kerja | AB1: OPD | AC1: Nama | AD1: No. HP | AE1: Email | AF1: Keterkaitan 58 Rencana Aksi | AG1: Frekuensi Penggunaan Aplikasi | AH1: TA
A2: 1 | B2: 2 | D2: 3 | E2: 4 | F2: 5 | G2: 6 | H2: 7 | I2: 8 | J2: 9 | K2: 10 | L2: 11 | M2: 12 | N2: 13 | O2: 14 | P2: 15 | Q2: 16 | R2: 17 | S2: 18 | T2: 19 | U2: 20 | V2: 21 | W2: 22 | X2: 23 | Y2: 24 | Z2: 25 | AA2: 26 | AB2: 27 | AC2: 28 | AD2: 29 | AE2: 30 | AF2: 31 | AG2: 32 | AH2: 33
A3: Panduan | B3: Isikan dengan nama layanan yang selenggarakan | D3: Layanan Pengaduan Masyarakat (LPM) adalah wadah atau sistem yang disediakan oleh instansi pemerintah (atau lembaga publik lainnya) bagi masyarakat untuk menyampaikan keluhan, saran, masukan, aspirasi, hingga laporan atas dugaan penyimpangan atau maladministrasi dalam penyelenggaraan pemerintahan dan pelayanan publik. | E3: Isikan dengan dasar hukum penyelenggaraan layanan (Isikan dengan peraturan tingkat daerah, jika tidak ada dapat mengacu ke peraturan tingkat pusat) | F3: isikan dengan link dokumen berbentuk pdf terkait SOP / Proses Bisnis layanan | G3: Isikan referensi layanan sesuai daftar (Isikan dengan referensi layanan yang mendekati, dapat dilihat pada sheet referensi) | H3: Isikan dengan penerima layanan | I3: Isikan dengan input data | J3: Isikan dengan output data | K3: Isikan dengan sifat data | L3: Apakah terdapat Data Pribadi yang digunakan ? | M3: Pemutakhiran data hasil dari proses layanan | N3: Masukan nama aplikasi pendukung layanan, jika tidak ada maka isikan dengan "Belum terdapat aplikasi" | O3: Isikan dengan pengembang aplikasi | P3: Isikan dengan pemilik aplikasi | Q3: Isikan dengan platform aplikasi | R3: Isikan dengan alamat akses aplikasi, jika berbasis mobile isikan dengan link download | S3: Isikan dengan metode akses aplikasi | T3: Isikan dengan jenis aplikasi, informasi untuk satu arah, transaksi untuk dua arah) | U3: Isikan dengan tahun pembuatan | V3: Isikan dengan status aplikasi | W3: Apakah aplikasi telah terintegrasi ? | X3: Terintegrasi dengan aplikasi ? (Isikan dengan nama aplikasi, jika tidak isikan Tidak Terintegrasi | Y3: Bagaimana proses integrasi berlangsung ? | Z3: Berapa lama integrasi data/layanan mutakhirkan ? | AA3: Isikan dengan unit kerja pelaksana layanan | AB3: Isikan dengan OPD pelaksana layanan | AC3: Isikan dengan Nama PIC pelaksana layanan | AD3: Isikan dengan nomor kontak pelaksana layanan | AE3: Isikan dengan email pelaksana layanan | AF3: Isikan keterkaitan layanan/probis/data dengan 58 Rencana Aksi. Sebutkan nomor rencana aksi tersebut. | AG3: Isikan sesuai dengan frekuensi penggunaan aplikasi. Harian / Mingguan / Bulanan / Tahunan / Insidentil
A4: Contoh | B4: Layanan Pengaduan Masyarakat | E4: Undang-Undang Nomor 25 Tahun 2009 tentang Pelayanan Publik | F4: abcd.pdf | G4: PENINGKATAN KUALITAS PELAYANAN PUBLIK | H4: Masyarakat | I4: Data Pengguna, Data Adun | J4: Data Aduan Masyarakat | K4: Tertutup | L4: Terdapat | M4: Harian | N4: SP4N Lapor | O4: Pusat | P4: Pusat | Q4: Website dan Mobile | R4: https://lapor.go.id/ | S4: Secara Online | T4: Transaksi | U4: 2018 | V4: Aktif | W4: Tidak | X4: Tidak Terintegrasi | Y4: Tidak Terintegrasi | Z4: Tidak Terintegrasi | AA4: Bidang Informasi Komunikasi Publik | AB4: Diskominfo | AC4: Rima Diani, S.Si.Kom | AD4: 123 | AE4: rima@bandungkab.go.id | AF4: 28 | AG4: Harian
A5: Diskominfo
A6: 1 | B6: Layanan Penerbitan Sertifikasi Elektronik | C6: Diskominfo | D6: layanan bagi para pejabat, Kepala Sekolah, dan Kepala Desa untuk memproleh Tanda tangan digital yang tersertifikasi BSSN | G6: MANAJEMEN KEAMANAN INFORMASI | H6: Instansi Pemerintah Lainnya | I6: Data Tanda Tangan Elektronik | J6: Data Tanda Tangan Elektronik | K6: Terbatas | M6: Tahunan | AA6: Persandian | AB6: Diskominfo
A7: 2 | B7: Layanan Radio Kandaga | C7: Diskominfo | D7: layanan bagi para pembicara yang telah menyampaiakan informasi melalui Podcast Radio Kandaga | G7: PENYIARAN RADIO PUBLIK | I7: Data Siaran atau Podcast | J7: Data Siaran atau Podcast | K7: Terbuka | M7: Tahunan | N7: KANDAGA | Q7: Mobile | R7: https://play.google.com/store/apps/details?id=com.diskominfo.radiokandagabedas&pcampaignid=web_share | AA7: Penyelenggaraan Informasi dan Komunikasi Publik | AB7: Diskominfo
A8: 3 | B8: Layanan Data Statisktik Sektoral | C8: Diskominfo | D8: memudahkan pengambilan keputusan yang akurat dari instansi pemerintah terkait, dapat dilakukan dengan pengujian terhadap system dan data sebelumnya dengan pembuatan aplikasi atau system informasi versi beta untuk menghasilkan analisa yang tepat serta sasaran yang akurat dari produk yang akan dihasilkan melalui produk kompilasi, produk survey, produk komparasi dan produk lainnya baik dari data sektoral suatu daerah yang akan digunakan nantinya untun meminimalisir masalah yang ada | G8: PENGELOLAAN DATA STATISTIK | H8: Instansi Pemerintah Lainnya | I8: Data Statistik Sektoral | J8: Data Statistik Sektoral | K8: Terbuka | M8: Tahunan | N8: SIMASDA | Q8: Website | R8: https://simasda.bandungkab.go.id/ | AA8: Statistik | AB8: Diskominfo
A9: 4 | B9: Layanan Domain dan Sub Domain | C9: Diskominfo | D9: membangun branding Pemerintah Kabupaten Bandung yaitu bandungkab.go.id | G9: PENATAKELOLAAN APLIKASI INFORMATIKA | H9: Masyarakat | I9: Data Domain dan Sub Domain | J9: Data Domain dan Sub Domain | K9: Terbatas | M9: Tahunan | AA9: TIK | AB9: Diskominfo
A10: 5 | B10: Layanan Cpanel | C10: Diskominfo | D10: menyelenggarakan website Desa dan Website SMP | G10: PENATAKELOLAAN APLIKASI INFORMATIKA | H10: Masyarakat | I10: Data Cpanel | J10: Data Cpanel | K10: Terbatas | M10: Tahunan | AA10: TIK | AB10: Diskominfo
A11: 6 | B11: Layanan SSL | C11: Diskominfo | D11: mengamankan lalu lintas data dari domain bandungkab.go.id beserta subdomainnya | G11: MANAJEMEN KEAMANAN INFORMASI | H11: Masyarakat | I11: Data SSL | J11: Data SSL | K11: Terbatas | M11: Tahunan | AA11: TIK | AB11: Diskominfo
A12: 7 | B12: Layanan Pengembangan Aplikasi | C12: Diskominfo | D12: Layanan Pengembangan Aplikasi: Menyediakan pembuatan aplikasi sesuai kebutuhan pemerintah daerah. | G12: PENATAKELOLAAN APLIKASI INFORMATIKA | H12: Instansi Pemerintah Lainnya | I12: Data Aplikasi | J12: Data Aplikasi | K12: Terbatas | M12: Tahunan | AA12: TIK | AB12: Diskominfo
A13: 8 | B13: Layanan Pembinaan dan Fasilitasi KIM | C13: Diskominfo | D13: Layanan Pembinaan dan Fasilitasi KIM: Mendorong pengembangan kawasan industri melalui pembinaan dan fasilitasi. | G13: PEMBERDAYAAN DAN PERAN MASYARAKAT | H13: Instansi Pemerintah Lainnya | I13: Data Peserta KIM | J13: Data Peserta KIM | K13: Terbatas | M13: Tahunan | N13: KIM | Q13: Website | R13: https://kimonline.bandungkab.go.id/ kim/ | AB13: Diskominfo
A14: 9 | B14: Layanan Informasi Publik Pejabat Pelaksana Informasi dan Dokumentasi (PPID) | C14: Diskominfo | D14: Layanan Informasi Publik PPID: Memberikan akses informasi publik dan dokumen pemerintah melalui pejabat pelaksana. | G14: PENGELOLAAN INFORMASI PUBLIK | H14: Instansi Pemerintah Lainnya | I14: Data PPID | J14: Data PPID | K14: Terbuka | M14: Bulanan | N14: PPID | Q14: Website | R14: http://ppid.bandungkab.go.id/ | AB14: Diskominfo
A15: 10 | B15: Layanan Helpdesk TIK | C15: Diskominfo | D15: Layanan Helpdesk TIK: Menyediakan bantuan dan dukungan teknis dalam penggunaan teknologi informasi dan komunikasi. | G15: PENATAKELOLAAN APLIKASI INFORMATIKA | H15: Instansi Pemerintah Lainnya | I15: Data Helpdesk TIK | J15: Data Helpdesk TIK | K15: Terbatas | M15: Tahunan | AB15: Diskominfo
A16: 11 | B16: Layanan Pengelolaan Jaringan dan Keamanan TIK | C16: Diskominfo | D16: Layanan Pengelolaan Jaringan dan Keamanan TIK: Menyediakan pengelolaan jaringan dan keamanan sistem teknologi informasi. | G16: PENATAKELOLAAN APLIKASI INFORMATIKA | H16: Instansi Pemerintah Lainnya | I16: Data Jaringan dan Keamanan TIK | J16: Data Jaringan dan Keamanan TIK | K16: Terbatas | M16: Tahunan | AB16: Diskominfo
A17: 12 | B17: Layanan Portal Aplikasi | C17: Diskominfo | D17: Layanan Portal Aplikasi: Memberikan akses terpadu ke berbagai aplikasi pemerintah daerah. | G17: PENATAKELOLAAN APLIKASI INFORMATIKA | H17: Instansi Pemerintah Lainnya | I17: Data Portal Layanan | J17: Data Portal Layanan | K17: Terbuka | M17: Tahunan | N17: PORTAL KAB BANDUNG | Q17: Website | R17: https://bandungkab.go.id/ | AB17: Diskominfo
A18: 13 | B18: Layanan Publikasi Infromasi dan Berita | C18: Diskominfo | D18: Layanan Publikasi Informasi dan Berita: Menyajikan informasi dan berita terkini terkait pemerintahan daerah. | G18: MANAJEMEN KEAMANAN INFORMASI | H18: Masyarakat | I18: Data Publikasi Informasi dan Berita | J18: Data Publikasi Informasi dan Berita | K18: Terbuka | M18: Tahunan | AB18: Diskominfo
A19: 14 | B19: Layanan Diskusi Publik | C19: Diskominfo | D19: Layanan Diskusi Publik: Memberikan platform untuk diskusi dan partisipasi masyarakat dalam pengambilan keputusan. | G19: PENGELOLAAN KOMUNIKASI PUBLIK | H19: Masyarakat | I19: Data Diskusi Publik | J19: Data Diskusi Publik | K19: Terbatas | M19: Tahunan | AB19: Diskominfo
A20: 15 | B20: Layanan Pengaduan Masyarakat | C20: Diskominfo | D20: Layanan Pengaduan Masyarakat: Memfasilitasi masyarakat untuk menyampaikan keluhan dan pengaduan terkait pelayanan publik. | G20: PENINGKATAN KUALITAS PELAYANAN PUBLIK | H20: Masyarakat | I20: Data Aduan Masyarakat | J20: Data Aduan Masyarakat | K20: Terbuka | M20: Bulanan | N20: SP4N Lapor | AB20: Diskominfo
A21: 16 | B21: Layanan Smart CIty | C21: Diskominfo | D21: Layanan Smart City: Mengintegrasikan teknologi untuk meningkatkan efisiensi dan kualitas hidup warga dalam konteks perkotaan. | G21: PENINGKATAN KUALITAS PELAYANAN PUBLIK | H21: Masyarakat | I21: Data Smart City | J21: Data Smart City | K21: Terbuka | M21: Tahunan | N21: SMART CITY | Q21: Website | R21: https://smartcity.bandungkab.go.id/ | AB21: Diskominfo
A22: BAGIAN PERENCKEU
A23: 1 | B23: Layanan Sistem Informasi Tindak Lanjut Hasil Layanan Terpadu | C23: BAGIAN PERENCKEU | D23: Layanan Sistem Informasi Tindak Lanjut Hasil Layanan Terpadu mengacu pada sistem informasi berbasis web untuk mengelola dan memantau proses tindak lanjut (TL) hasil rekomendasi pemeriksaan oleh lembaga seperti Badan Pemeriksa Keuangan (BPK), agar prosesnya menjadi lebih efisien, transparan, dan akuntabel melalui digitalisasi data dan komunikasi online secara real-time antara BPK dan entitas yang diperiksa. | E23: Undang-Undang Nomor 25 Tahun 2009 tentang Pelayanan Publik, Peraturan Pemerintah Nomor 96 Tahun 2012 | G23: PENINGKATAN KUALITAS PELAYANAN PUBLIK | H23: Instansi Pemerintah Lainnya | I23: Data Evidence Tindak Lanjut yang Direkomendasikan | J23: Data Hasil Tindak Lanjut | K23: Terbatas | L23: Tidak terdapat | M23: Tahunan | N23: SIMASLAHAT | O23: Pihak Ke 3 | P23: Kab. Bandung | Q23: Website | R23: https://simaslahat.bandungkab.go.id | S23: Secara Online | T23: Transaksi | U23: 2022 | V23: Aktif | W23: Tidak | X23: Tidak Terintegrasi | Y23: Tidak Terintegrasi | Z23: Tidak Terintegrasi | AA23: Bagian Perencanaan dan Keuangan | AB23: Setda | AC23: VERRYNOVYANDI SADIKIN, SE., MM | AD23: 895327038135 | AE23: setdakab.bdg@gmail.com | AF23: - | AG23: Tahunan
A24: 2 | B24: Layanan Pengaduan Masyarakat | C24: BAGIAN PERENCKEU | D24: Layanan Pengaduan Masyarakat (LPM) adalah wadah atau sistem yang disediakan oleh instansi pemerintah (atau lembaga publik lainnya) bagi masyarakat untuk menyampaikan keluhan, saran, masukan, aspirasi, hingga laporan atas dugaan penyimpangan atau maladministrasi dalam penyelenggaraan pemerintahan dan pelayanan publik. | E24: Undang-Undang Nomor 25 Tahun 2009 tentang Pelayanan Publik | G24: PENINGKATAN KUALITAS PELAYANAN PUBLIK | H24: Masyarakat | I24: Data Pengguna, Data Adun | J24: Data Aduan Masyarakat | K24: Terbatas | L24: Terdapat | M24: Harian | N24: SP4N Lapor | O24: Pusat | P24: Pusat | Q24: Website | R24: https://lapor.go.id/ | S24: Secara Online | T24: Informasi | U24: 2018 | V24: Aktif | W24: Tidak | X24: Tidak Terintegrasi | Y24: Tidak Terintegrasi | Z24: Tidak Terintegrasi | AA24: Bidang Informasi Komunikasi Publik | AB24: Diskominfo | AC24: ALIPHIO DYAKSHA PUTRA, A.Md.Ak. | AD24: 8988005270 | AE24: setdakab.bdg@gmail.com | AF24: - | AG24: Insidentil
A25: 3 | B25: Layanan Data Sektoral | C25: BAGIAN PERENCKEU | D25: Layanan data sektoral adalah statistik yang dihasilkan oleh instansi pemerintah pusat atau daerah sesuai dengan tugas dan fungsi masing-masing, yang bertujuan untuk memenuhi kebutuhan internal instansi tersebut dalam penyelenggaraan pemerintahan dan pembangunan. | E25: PERATURAN BADAN PUSAT STATISTIK NOMOR 3 TAHUN 2022 TENTANG EVALUASI PENYELENGGARAAN STATISTIK SEKTORAL | G25: PENGELOLAAN DATA STATISTIK | H25: Instansi Pemerintah Lainnya | I25: Data Sektoral | J25: Data Sektoral | K25: Terbatas | L25: Tidak terdapat | M25: Tahunan | N25: SIMASDA | O25: Pihak Ke 3 | P25: Kab. Bandung | Q25: Website | R25: https://simasda.bandungkab.go.id/ | S25: Secara Online | T25: Informasi | U25: 2022 | V25: Aktif | W25: Ya | X25: Terintegrasi dengan Bedas, E-Walidata dan Satu Data Kab Bandung | Y25: Database to Database | Z25: Realtime | AA25: Bidang Statistik | AB25: Diskominfo | AC25: DHANTI AURILIA PRATIWI, M.Stat | AD25: 81904085710 | AE25: setdakab.bdg@gmail.com
A26: 4 | B26: Layanan Rekonsiliasi Pajak Pusat | C26: BAGIAN PERENCKEU | D26: Rekonsiliasi pajak pusat atas belanja daerah adalah proses penyesuaian atau pencocokan antara jumlah pajak yang harus dibayarkan oleh pemerintah daerah kepada pemerintah pusat dengan total belanja yang telah dilakukan oleh pemerintah daerah dalam kerangka Anggaran Pendapatan dan Belanja Daerah (APBD) | E26: PERBUP Nomor 165 Tahun 2021 dan PERBUP Nomor 289 Tahun 2022 | G26: AKUNTANSI DAN PELAPORAN KEUANGAN | H26: Instansi Pemerintah Lainnya | I26: Data Pajak Pusat (ID Billing & NTPN) | J26: Rekap Data Pajak Pusat | K26: Terbatas | L26: Tidak terdapat | M26: Bulanan | N26: SIREKON | O26: Diskominfo | P26: Kab. Bandung | Q26: Website | R26: https://sirekonpajak.bandungkab.go.id/ | S26: Secara Online | T26: Informasi | U26: 2020 | V26: Aktif | W26: Tidak | X26: Tidak Terintegrasi | Y26: Tidak Terintegrasi | Z26: Tidak Terintegrasi | AA26: Bagian Perencanaan dan Keuangan | AB26: Setda | AC26: VERRYNOVYANDI SADIKIN, SE., MM | AD26: 895327038135 | AE26: setdakab.bdg@gmail.com | AF26: - | AG26: Bulanan
A27: 5 | B27: Layanan Pajak | C27: BAGIAN PERENCKEU | D27: Fungsi layanan pajak meliputi pengumpulan pajak daerah, pengelolaan data wajib pajak, pengawasan kepatuhan, serta penyediaan kemudahan pembayaran menggunakan aplikasi digital yang mendukung optimalisasi penerimaan pajak dan peningkatan kualitas pelayanan kepada masyarakat. | E27: UU No. 1 Tahun 2022 | G27: AKUNTANSI DAN PELAPORAN KEUANGAN | H27: Instansi Pemerintah Lainnya | I27: Data Pajak | J27: ID Billing | K27: Terbatas | L27: Terdapat | M27: Harian | N27: Coretax | O27: Pusat | P27: Pusat | Q27: Website | R27: coretaxdjp.pajak.go.id | S27: Secara Online | T27: Informasi | U27: 2025 | V27: Aktif | W27: Tidak | X27: Tidak Terintegrasi | Y27: Tidak Terintegrasi | Z27: Tidak Terintegrasi | AA27: Bagian Perencanaan dan Keuangan | AB27: Setda | AC27: VERRYNOVYANDI SADIKIN, SE., MM | AD27: 895327038135 | AE27: setdakab.bdg@gmail.com | AF27: - | AG27: Harian
A28: 6 | B28: Layanan Pajak Daerah | C28: BAGIAN PERENCKEU | D28: Pajak daerah yang ada digunakan untuk membiayai semua kepentingan umum. Termasuk untuk membuka lapangan kerja baru, sehingga terjadi pemerataan pendapatan agar kesenjangan ekonomi antara yang kaya dan miskin tidak terlalu menonjol. Pajak daerah diharapkan dapat meningkatkan pemerataan di setiap daerah. | E28: Undang-Undang Nomor 28 Tahun 2009 tentang Pajak Daerah dan Retribusi Daerah (UU PDRD) | G28: AKUNTANSI DAN PELAPORAN KEUANGAN | H28: Instansi Pemerintah Lainnya | I28: Data Pajak Daerah | J28: Data Rekap Pajak Daerah | K28: Terbatas | L28: Tidak terdapat | M28: Harian | N28: E-SPTPD | O28: Diskominfo | P28: Kab. Bandung | Q28: Website | R28: https://e-sptpd.bandungkab.go.id/ | S28: Secara Online | T28: Informasi | U28: 2019 | V28: Aktif | W28: Tidak | X28: Tidak Terintegrasi | Y28: Tidak Terintegrasi | Z28: Tidak Terintegrasi | AA28: Bagian Perencanaan dan Keuangan | AB28: Setda, Bapenda | AC28: VERRYNOVYANDI SADIKIN, SE., MM | AD28: 895327038135 | AE28: setdakab.bdg@gmail.com | AF28: - | AG28: Harian
A29: 7 | B29: Layanan Transaksi | C29: BAGIAN PERENCKEU | D29: Fungsi utama layanan transaksi di Kabupaten Bandung adalah untuk memudahkan masyarakat dalam memenuhi kewajiban pembayaran pajak daerah dan mendukung efisiensi pengelolaan pajak oleh pemerintah daerah. Layanan ini meliputi berbagai fasilitas dan sistem, seperti pengesahan STNK, pembayaran PKB, dan pemanfaatan teknologi untuk pelaporan data transaksi usaha secara online. | E29: Peraturan Bupati (Perbup) Kabupaten Bandung Nomor 22 Tahun 2018 tentang Implementasi Transaksi Non Tunai, yang telah beberapa kali diubah dengan Perbup Nomor 6 Tahun 2020 dan Perbup Nomor 15 Tahun 2020. | G29: AKUNTANSI DAN PELAPORAN KEUANGAN | H29: Instansi Pemerintah Lainnya | I29: Data Transaksi | J29: Data Rekening Koran | K29: Terbatas | L29: Tidak terdapat | M29: Lainnya | N29: IBC (Internet Banking Corporate) | O29: Pihak Ke 3 | P29: Pihak Ke 3 (Lisensi) | Q29: Desktop | R29: Aplikasi dari BJB | S29: Secara Online | T29: Transaksi | U29: 2019 | V29: Aktif | W29: Tidak | X29: Tidak Terintegrasi | Y29: Tidak Terintegrasi | Z29: Tidak Terintegrasi | AA29: Bagian Perencanaan dan Keuangan | AB29: Setda | AC29: VERRYNOVYANDI SADIKIN, SE., MM | AD29: 895327038135 | AE29: setdakab.bdg@gmail.com | AF29: - | AG29: Harian
A30: 8 | B30: Layanan Penatausahaan Keuangan | C30: BAGIAN PERENCKEU | D30: Fungsi layanan penatausahaan keuangan di Kabupaten Bandung adalah mencatat dan menyimpan semua transaksi penerimaan dan pengeluaran kas daerah secara akurat dan tertib untuk penyusunan laporan keuangan, pengendalian APBD, serta penyediaan data dan informasi keuangan yang dapat dipertanggungjawabkan. Penatausahaan ini mendukung efektivitas pengelolaan keuangan daerah dan memastikan transparansi serta akuntabilitas dalam penggunaan dana publik. | E30: Peraturan Bupati (Perbup) Kabupaten Bandung Nomor 48 Tahun 2025 tentang Perubahan Atas Peraturan Bupati Nomor 83 Tahun 2024 | G30: AKUNTANSI DAN PELAPORAN KEUANGAN | H30: Instansi Pemerintah Lainnya | I30: Data APBD | J30: Data APBD | K30: Tertutup | L30: Terdapat | M30: Lainnya | N30: SIPD | O30: Pusat | P30: Pusat | Q30: Website | R30: SIPD.kemendagri.go.id | S30: Secara Online | T30: Transaksi | U30: 2021 | V30: Aktif | W30: Tidak | X30: Tidak Terintegrasi | Y30: Tidak Terintegrasi | Z30: Tidak Terintegrasi | AA30: Bagian Perencanaan dan Keuangan | AB30: Setda | AC30: VERRYNOVYANDI SADIKIN, SE., MM | AD30: 895327038135 | AE30: setdakab.bdg@gmail.com | AF30: - | AG30: Harian
A31: 10 | B31: Layanan Tata Naskah Dinas | C31: BAGIAN PERENCKEU | D31: Fungsi utama layanan Tata Naskah Dinas (TND) di Kabupaten Bandung adalah untuk menciptakan kelancaran komunikasi tertulis yang efektif dan efisien, memastikan keotentikan, keterpercayaan, kepastian, dan akuntabilitas informasi, serta mendukung terwujudnya tata kelola pemerintahan yang baik (good governance) melalui penerapan penggunaan naskah dinas secara elektronik. TND juga berfungsi sebagai sarana untuk mengatur jenis dan penyusunan naskah dinas, penggunaan lambang negara dan cap dinas, serta penggunaan bahasa Indonesia yang sesuai dalam komunikasi resmi. | E31: Peraturan Bupati (PERBUP) Nomor 82 Tahun 2024 tentang Pedoman Tata Naskah Dinas di Lingkungan Pemerintah Kabupaten Bandung. | G31: PENATAAN SISTEM TATA LAKSANA | H31: Instansi Pemerintah Lainnya | I31: Naskah Surat | J31: Surat yang dilegalisasi | K31: Terbatas | L31: Tidak terdapat | M31: Harian | N31: SULTAN (e-office) | O31: Diskominfo | P31: Kab. Bandung | Q31: Website dan Mobile | R31: https://sultan.bandungkab.go.id/ | S31: Secara Online | T31: Informasi | U31: 2025 | V31: Aktif | W31: Ya | X31: Terintegrasi dengan SIPPHADE, dll | Y31: Web Service | Z31: Realtime | AA31: Semua Bagian | AB31: Setda | AC31: ALIPHIO DYAKSHA PUTRA, A.Md.Ak. | AD31: 8988005270 | AE31: setdakab.bdg@gmail.com | AF31: - | AG31: Harian
A32: 11 | B32: Layanan Perencanaan BMD | C32: BAGIAN PERENCKEU | D32: Untuk mengidentifikasi kebutuhan aset, merencanakan pengadaan, pemanfaatan, pemeliharaan, dan pengelolaan aset agar sesuai dengan tugas dan fungsi SKPD, mendukung pelayanan publik, dan memastikan pengelolaan yang akuntabel dan transparan sesuai regulasi. Layanan ini bertujuan untuk menciptakan pengelolaan aset yang efisien dan efektif, mencegah pemborosan, serta mengoptimalkan penggunaan aset daerah untuk pembangunan. | E32: Undang-Undang Nomor 1 Tahun 2004 tentang Perbendaharaan Negara, Peraturan Pemerintah Nomor 27 Tahun 2014 tentang Pengelolaan BMD. | G32: PERENCANAAN PEMBANGUNAN | H32: Instansi Pemerintah Lainnya | I32: Data Kebutuhan Aset | J32: Pengadaan Aset | K32: Terbatas | L32: Tidak terdapat | M32: Tahunan | N32: E-Planning BMD | O32: OPD | P32: Kab. Bandung | Q32: Website | R32: sshsbu.e-planningbmd.id | S32: Secara Online | T32: Informasi | V32: Aktif | W32: Tidak | X32: Tidak Terintegrasi | Y32: Tidak Terintegrasi | Z32: Tidak Terintegrasi | AA32: Bagian Perencanaan dan Keuangan | AB32: BKAD | AC32: YATI KURNIATI, SE., M.K.P. | AD32: 81321814674 | AE32: bagianprogramsetdakab.bandung@gmail.com | AF32: - | AG32: Tahunan
A33: 12 | B33: Layanan Statistik | C33: BAGIAN PERENCKEU | D33: Indonesia Data Hub merupakan one stop collaboration platform yang bertujuan untuk meningkatkan literasi data dan value of statistics serta mendukung interoperabilitas data dan kolaborasi eksplorasi terhadap data. | E33: Undang-Undang Nomor 16 Tahun 1997 tentang Statistik sebagai dasar umum, serta Peraturan Presiden Nomor 86 Tahun 2007 dan Peraturan Kepala Badan Pusat Statistik (BPS) Nomor 78 Tahun 2020 yang mengatur pelayanan statistik terpadu di tingkat pusat. | G33: PENGELOLAAN DATA STATISTIK | H33: Instansi Pemerintah Lainnya | I33: Metadata dan Standar Data Statistik | J33: Metadata dan Standar Data Statistik | K33: Terbuka | L33: Tidak terdapat | M33: Lainnya | N33: INDAH | O33: Pusat | P33: Pusat | Q33: Website | R33: https://indah.bps.go.id/ | S33: Secara Online | T33: Informasi | U33: 2019 | V33: Aktif | W33: Ya | X33: Terintegrasi dengan Aplikasi Romantik | Y33: Web Service | Z33: Realtime | AA33: Bagian Perencanaan dan Keuangan | AB33: Setda | AC33: DHANTI AURILIA PRATIWI, M.Stat | AD33: 81904085710 | AE33: setdakab.bdg@gmail.com | AF33: - | AG33: Tahunan
A34: 13 | B34: Layanan Informasi Pengawasan SAKIP, SPIP, MR | C34: BAGIAN PERENCKEU | D34: Fungsinya adalah menyediakan data dan laporan pengawasan yang terintegrasi untuk mendukung perbaikan tata kelola, meningkatkan transparansi, mengurangi potensi penyimpangan, dan memperkuat pengambilan keputusan berbasis bukti dalam rangka mewujudkan pemerintahan yang efektif, efisien, dan akuntabel. | E34: Nomor 60 Tahun 2008 tentang Sistem Pengendalian Intern Pemerintah (SPIP), Peraturan Presiden (Perpres) Nomor 29 Tahun 2014 tentang Sistem Akuntabilitas Kinerja Instansi Pemerintah (SAKIP). | G34: PENINGKATAN KUALITAS PELAYANAN PUBLIK | H34: Instansi Pemerintah Lainnya | I34: Data Evidence SAKIP, SPIP, MR | J34: Nilai SAKIP dan MR | K34: Terbatas | L34: Tidak terdapat | M34: Tahunan | N34: SIMWAS | O34: Pihak Ke 3 | P34: Kab. Bandung | Q34: Website | R34: simwas.bandungkab.go.id | S34: Secara Online | T34: Transaksi | U34: 2022 | V34: Aktif | W34: Tidak | X34: Tidak Terintegrasi | Y34: Tidak Terintegrasi | Z34: Tidak Terintegrasi | AA34: Bagian Perencanaan dan Keuangan | AB34: Setda, Inspektorat | AC34: DEBI RIANA S.STP., M.Si. | AD34: 8127392553 | AE34: setdakab.bdg@gmail.com | AF34: mungkin berkaitan dengan 27 | AG34: Tahunan
A35: 14 | B35: Layanan Informasi Data, Pengendalian, Evaluasi, dan Pelaporan | C35: BAGIAN PERENCKEU | D35: Mencakup penyediaan dan pengelolaan data dan informasi pembangunan, pemantauan dan pengendalian pelaksanaan program/kegiatan, serta penyusunan laporan hasil evaluasi untuk mendukung perumusan kebijakan dan pengambilan keputusan. Layanan ini bertugas menganalisis data, mengoordinasikan evaluasi, dan menyusun pelaporan program pembangunan daerah. | E35: Undang-Undang Nomor 14 Tahun 2008 tentang Keterbukaan Informasi Publik, Undang-Undang Nomor 25 Tahun 2009 tentang Pelayanan Publik. | G35: PENINGKATAN KUALITAS REFORMASI BIROKRASI, PENGAWASAN, DAN AKUNTABILITAS KINERJA | H35: Instansi Pemerintah Lainnya | I35: Data Kinerja dan Realisasi Anggaran | J35: Data Capaian Kinerja dan Realisasi Anggaran | K35: Terbatas | L35: Tidak terdapat | M35: Lainnya | N35: SIDALMONEP | O35: OPD | P35: Kab. Bandung | Q35: Website | R35: sidalmonep.bandungkab.go.id/ | S35: Secara Online | T35: Informasi | U35: 2021 | V35: Aktif | W35: Tidak | X35: SIPD | Y35: API | Z35: Realtime | AA35: Bagian Perencanaan dan Keuangan | AB35: Setda, Bapperida | AC35: YATI KURNIATI, SE., M.K.P. | AD35: 81321814674 | AE35: bagianprogramsetdakab.bandung@gmail.com | AF35: - | AG35: Tahunan
A36: BAGIAN UMUM
A37: 15 | B37: Layanan Pengelolaan Administrasi Kepegawaian | C37: BAGIAN UMUM | D37: mengelola administrasi, pengembangan, dan pelayanan pegawai secara efektif untuk mendukung kinerja Sekretariat Daerah. Fungsinya meliputi penyiapan bahan kebijakan, manajemen mutasi, kenaikan pangkat, pensiun, disiplin, hingga pengembangan kompetensi pegawai | E37: Undang-Undang Nomor 20 Tahun 2023 tentang Aparatur Sipil Negara | G37: PENATAAN SUMBER DAYA MANUSIA APARATUR | H37: Pegawai | I37: Data Kepegawaian | J37: Data Kepegawaian | K37: Terbatas | L37: Terdapat | M37: Harian | N37: SIMPEL BKPSDM | O37: Diskominfo | P37: Kab. Bandung | Q37: Website | R37: https://simpelbkpsdm.bandungkab.go.id/ | S37: Secara Online | T37: Informasi | V37: Aktif | W37: Ya | X37: Terintegrasi | Y37: Database to Database | Z37: Realtime | AA37: Bagian Umum | AB37: Setda | AC37: Iman Herman Sudrajat, S.IP. | AE37: bag_umum@bandungkab.go.id | AF37: 28 | AG37: Harian
A38: 16 | B38: Layanan Surat Masuk dan Penomoran Surat Keluar | C38: BAGIAN UMUM | D38: mengelola tata usaha, surat-menyurat, dan arsip secara tertib, aman, dan efisien. Fungsinya meliputi pengendalian naskah dinas masuk/keluar, penataan kearsipan, serta memfasilitasi administrasi pimpinan, staf ahli, dan perangkat daerah guna mendukung kelancaran kebijakan | E38: Peraturan Bupati (PERBUP) Nomor 82 Tahun 2024 tentang Pedoman Tata Naskah Dinas di Lingkungan Pemerintah Kabupaten Bandung. | G38: PENINGKATAN KUALITAS PELAYANAN PUBLIK | H38: Instansi Pemerintah Lainnya | I38: Surat Masuk. Naskah Dinas | J38: Nomor Surat | K38: Terbatas | L38: Tidak terdapat | M38: Harian | N38: SULTAN (E-Office) | O38: Diskominfo | P38: Kab. Bandung | Q38: Website | R38: https://sultan.bandungkab.go.id/ | S38: Secara Online | T38: Informasi | V38: Aktif | W38: Ya | X38: Terintegrasi | Y38: Database to Database | Z38: Realtime | AA38: Bagian Umum | AB38: Setda | AC38: Iman Herman Sudrajat, S.IP. | AE38: bag_umum@bandungkab.go.id | AF38: 28 | AG38: Harian
A39: 16 | B39: Layanan Piagam Penghargaan Bupati Bandung | C39: BAGIAN UMUM | D39: Layanan Fasilitasi Piagam Penghargaan Bupati berupa administrasi penerbitan, penyiapan naskah, dan pendokumentasian piagam penghargaan Bupati Bandung | E39: Peraturan Bupati (PERBUP) Nomor 82 Tahun 2024 tentang Pedoman Tata Naskah Dinas di Lingkungan Pemerintah Kabupaten Bandung. | G39: PENINGKATAN KUALITAS PELAYANAN PUBLIK | H39: Instansi Pemerintah Lainnya | I39: Permohonan Piagam | J39: Naskah dan Dokumen Piagam | K39: Terbatas | L39: Tidak terdapat | M39: Lainnya | N39: Microsoft Excel | O39: OPD | P39: Kab. Bandung | Q39: Desktop | R39: - | S39: Secara Offline | T39: Informasi | V39: Aktif | W39: Tidak | X39: Tidak Terintegrasi | Y39: Tidak Terintegrasi | Z39: Tidak Terintegrasi | AA39: Bagian Umum | AB39: Setda | AC39: Iman Herman Sudrajat, S.IP. | AE39: bag_umum@bandungkab.go.id | AF39: 28 | AG39: Harian
A40: BAGIAN ORGANISASI
...

Sheet cleansing Kertas Kerja
A1: No | B1: Nama Layanan | C1: Tujuan dan Fungsi Layanan | D1: Dasar Hukum Layanan | E1: SOP / Proses Bisnis Layanan | F1: Referensi Layanan | G1: Target Layanan | H1: Data yang dimasukan | I1: Data yang dihasilkan | J1: Sifat Data | K1: Data Pribadi | L1: Interval update data yang dihasilkan | M1: Aplikasi Pendukung | N1: Pengembang | O1: Pemilik | P1: Platform | Q1: Alamat Aplikasi | R1: Kategori Akses | S1: Jenis Aplikasi | T1: Tahun Pembuatan | U1: Status Aplikasi | V1: Telah Terintegrasi | W1: Terintegrasi dengan Aplikasi | X1: Mekanisme Integrasi | Y1: Frekuensi Sinkronisasi | Z1: Bidang / Unit Kerja | AA1: OPD | AB1: Nama | AC1: No. HP | AD1: Email | AE1: Keterkaitan 58 Rencana Aksi | AF1: Frekuensi Penggunaan Aplikasi | AG1: TA
A2: 1 | B2: 2 | C2: 3 | D2: 4 | E2: 5 | F2: 6 | G2: 7 | H2: 8 | I2: 9 | J2: 10 | K2: 11 | L2: 12 | M2: 13 | N2: 14 | O2: 15 | P2: 16 | Q2: 17 | R2: 18 | S2: 19 | T2: 20 | U2: 21 | V2: 22 | W2: 23 | X2: 24 | Y2: 25 | Z2: 26 | AA2: 27 | AB2: 28 | AC2: 29 | AD2: 30 | AE2: 31 | AF2: 32 | AG2: 33
A3: 1 | B3: Layanan Radio Kandaga | C3: layanan bagi para pembicara yang telah menyampaiakan informasi melalui Podcast Radio Kandaga | F3: PENYIARAN RADIO PUBLIK | G3: Masyarakat | H3: Data Siaran atau Podcast | I3: Data Siaran atau Podcast | J3: Terbuka | L3: Tahunan | M3: KANDAGA | P3: Mobile | Q3: https://play.google.com/store/apps/details?id=com.diskominfo.radiokandagabedas&pcampaignid=web_share | Z3: Penyelenggaraan Informasi dan Komunikasi Publik | AA3: Diskominfo
A4: 2 | B4: Layanan Pembinaan dan Fasilitasi KIM | C4: Layanan Pembinaan dan Fasilitasi KIM: Mendorong pengembangan kawasan industri melalui pembinaan dan fasilitasi. | F4: PEMBERDAYAAN DAN PERAN MASYARAKAT | G4: Instansi Pemerintah Lainnya | H4: Data Peserta KIM | I4: Data Peserta KIM | J4: Terbatas | L4: Tahunan | M4: KIM | O4: Pusat | P4: Website | Q4: https://kimonline.bandungkab.go.id/ kim/ | AA4: Diskominfo
A5: 3 | B5: Layanan Portal Aplikasi | C5: Layanan Portal Aplikasi: Memberikan akses terpadu ke berbagai aplikasi pemerintah daerah. | F5: PENATAKELOLAAN APLIKASI INFORMATIKA | G5: Instansi Pemerintah Lainnya | H5: Data Portal Layanan | I5: Data Portal Layanan | J5: Terbuka | L5: Tahunan | M5: PORTAL KAB BANDUNG | N5: Diskominfo | O5: Kab. Bandung | P5: Website | Q5: https://bandungkab.go.id/ | AA5: Diskominfo
A6: 4 | B6: Layanan Smart CIty | C6: Layanan Smart City: Mengintegrasikan teknologi untuk meningkatkan efisiensi dan kualitas hidup warga dalam konteks perkotaan. | F6: PENINGKATAN KUALITAS PELAYANAN PUBLIK | G6: Masyarakat | H6: Data Smart City | I6: Data Smart City | J6: Terbuka | L6: Tahunan | M6: SMART CITY | P6: Website | Q6: https://smartcity.bandungkab.go.id/ | AA6: Diskominfo
A7: 5 | B7: Layanan Sistem Informasi Tindak Lanjut Hasil Layanan Terpadu | C7: Layanan Sistem Informasi Tindak Lanjut Hasil Layanan Terpadu mengacu pada sistem informasi berbasis web untuk mengelola dan memantau proses tindak lanjut (TL) hasil rekomendasi pemeriksaan oleh lembaga seperti Badan Pemeriksa Keuangan (BPK), agar prosesnya menjadi lebih efisien, transparan, dan akuntabel melalui digitalisasi data dan komunikasi online secara real-time antara BPK dan entitas yang diperiksa. | D7: Undang-Undang Nomor 25 Tahun 2009 tentang Pelayanan Publik, Peraturan Pemerintah Nomor 96 Tahun 2012 | F7: PENINGKATAN KUALITAS PELAYANAN PUBLIK | G7: Instansi Pemerintah Lainnya | H7: Data Evidence Tindak Lanjut yang Direkomendasikan | I7: Data Hasil Tindak Lanjut | J7: Terbatas | K7: Tidak terdapat | L7: Tahunan | M7: SIMASLAHAT | N7: Pihak Ke 3 | O7: Kab. Bandung | P7: Website | Q7: https://simaslahat.bandungkab.go.id | R7: Secara Online | S7: Transaksi | T7: 2022 | U7: Aktif | V7: Tidak | W7: Tidak Terintegrasi | X7: Tidak Terintegrasi | Y7: Tidak Terintegrasi | Z7: Bagian Perencanaan dan Keuangan | AA7: Setda | AB7: VERRYNOVYANDI SADIKIN, SE., MM | AC7: 895327038135 | AD7: setdakab.bdg@gmail.com | AE7: - | AF7: Tahunan
A8: 6 | B8: Layanan Pengaduan Masyarakat | C8: Layanan Pengaduan Masyarakat (LPM) adalah wadah atau sistem yang disediakan oleh instansi pemerintah (atau lembaga publik lainnya) bagi masyarakat untuk menyampaikan keluhan, saran, masukan, aspirasi, hingga laporan atas dugaan penyimpangan atau maladministrasi dalam penyelenggaraan pemerintahan dan pelayanan publik. | D8: Undang-Undang Nomor 25 Tahun 2009 tentang Pelayanan Publik | F8: PENINGKATAN KUALITAS PELAYANAN PUBLIK | G8: Masyarakat | H8: Data Pengguna, Data Adun | I8: Data Aduan Masyarakat | J8: Terbatas | K8: Terdapat | L8: Harian | M8: SP4N Lapor | N8: Pusat | O8: Pusat | P8: Website | Q8: https://lapor.go.id/ | R8: Secara Online | S8: Informasi | T8: 2018 | U8: Aktif | V8: Tidak | W8: Tidak Terintegrasi | X8: Tidak Terintegrasi | Y8: Tidak Terintegrasi | Z8: Bidang Informasi Komunikasi Publik | AA8: Diskominfo | AB8: ALIPHIO DYAKSHA PUTRA, A.Md.Ak. | AC8: 8988005270 | AD8: setdakab.bdg@gmail.com | AE8: - | AF8: Insidentil
A9: 7 | B9: Layanan Data Sektoral | C9: Layanan data sektoral adalah statistik yang dihasilkan oleh instansi pemerintah pusat atau daerah sesuai dengan tugas dan fungsi masing-masing, yang bertujuan untuk memenuhi kebutuhan internal instansi tersebut dalam penyelenggaraan pemerintahan dan pembangunan. | D9: PERATURAN BADAN PUSAT STATISTIK NOMOR 3 TAHUN 2022 TENTANG EVALUASI PENYELENGGARAAN STATISTIK SEKTORAL | F9: PENGELOLAAN DATA STATISTIK | G9: Instansi Pemerintah Lainnya | H9: Data Sektoral | I9: Data Sektoral | J9: Terbatas | K9: Tidak terdapat | L9: Tahunan | M9: SIMASDA | N9: Diskominfo | O9: Kab. Bandung | P9: Website | Q9: https://simasda.bandungkab.go.id/ | R9: Secara Online | S9: Informasi | T9: 2022 | U9: Aktif | V9: Ya | W9: Terintegrasi dengan Bedas, E-Walidata dan Satu Data Kab Bandung | X9: Database to Database | Y9: Realtime | Z9: Bidang Statistik | AA9: Diskominfo | AB9: DHANTI AURILIA PRATIWI, M.Stat | AC9: 81904085710 | AD9: setdakab.bdg@gmail.com
A10: 8 | B10: Layanan Rekonsiliasi Pajak Pusat | C10: Rekonsiliasi pajak pusat atas belanja daerah adalah proses penyesuaian atau pencocokan antara jumlah pajak yang harus dibayarkan oleh pemerintah daerah kepada pemerintah pusat dengan total belanja yang telah dilakukan oleh pemerintah daerah dalam kerangka Anggaran Pendapatan dan Belanja Daerah (APBD) | D10: PERBUP Nomor 165 Tahun 2021 dan PERBUP Nomor 289 Tahun 2022 | F10: AKUNTANSI DAN PELAPORAN KEUANGAN | G10: Instansi Pemerintah Lainnya | H10: Data Pajak Pusat (ID Billing & NTPN) | I10: Rekap Data Pajak Pusat | J10: Tertutup | K10: Terdapat | L10: Harian | M10: SIREKON | N10: Pihak Ke 3 | O10: Kab. Bandung | P10: Website | Q10: https://sirekonpajak.bandungkab.go.id/ | R10: Secara Online | S10: Informasi | T10: 2020 | U10: Aktif | V10: Tidak | W10: Tidak Terintegrasi | X10: Tidak Terintegrasi | Y10: Tidak Terintegrasi | Z10: Bagian Perencanaan dan Keuangan | AA10: BKAD | AB10: VERRYNOVYANDI SADIKIN, SE., MM | AC10: 895327038135 | AD10: setdakab.bdg@gmail.com | AE10: - | AF10: Bulanan
A11: 9 | B11: Layanan Pajak | C11: Fungsi layanan pajak meliputi pengumpulan pajak daerah, pengelolaan data wajib pajak, pengawasan kepatuhan, serta penyediaan kemudahan pembayaran menggunakan aplikasi digital yang mendukung optimalisasi penerimaan pajak dan peningkatan kualitas pelayanan kepada masyarakat. | D11: UU No. 1 Tahun 2022 | F11: AKUNTANSI DAN PELAPORAN KEUANGAN | G11: Instansi Pemerintah Lainnya | H11: Data Pajak | I11: ID Billing | J11: Terbatas | K11: Terdapat | L11: Harian | M11: Coretax | N11: Pusat | O11: Pusat | P11: Website | Q11: coretaxdjp.pajak.go.id | R11: Secara Online | S11: Informasi | T11: 2025 | U11: Aktif | V11: Tidak | W11: Tidak Terintegrasi | X11: Tidak Terintegrasi | Y11: Tidak Terintegrasi | Z11: Bagian Perencanaan dan Keuangan | AA11: BKAD | AB11: VERRYNOVYANDI SADIKIN, SE., MM | AC11: 895327038135 | AD11: setdakab.bdg@gmail.com | AE11: - | AF11: Harian
A12: 10 | B12: Layanan Pajak Daerah | C12: Pajak daerah yang ada digunakan untuk membiayai semua kepentingan umum. Termasuk untuk membuka lapangan kerja baru, sehingga terjadi pemerataan pendapatan agar kesenjangan ekonomi antara yang kaya dan miskin tidak terlalu menonjol. Pajak daerah diharapkan dapat meningkatkan pemerataan di setiap daerah. | D12: Undang-Undang Nomor 28 Tahun 2009 tentang Pajak Daerah dan Retribusi Daerah (UU PDRD) | F12: AKUNTANSI DAN PELAPORAN KEUANGAN | G12: Instansi Pemerintah Lainnya | H12: Data Pajak Daerah | I12: Data Rekap Pajak Daerah | J12: Terbatas | K12: Tidak terdapat | L12: Harian | M12: E-SPTPD | N12: Pihak Ke 3 | O12: Kab. Bandung | P12: Website dan Mobile | Q12: https://e-sptpd.bandungkab.go.id/ | R12: Secara Online | S12: Informasi | T12: 2019 | U12: Aktif | V12: Tidak | W12: Tidak Terintegrasi | X12: Tidak Terintegrasi | Y12: Tidak Terintegrasi | Z12: Bagian Perencanaan dan Keuangan | AA12: Setda, Bapenda | AB12: VERRYNOVYANDI SADIKIN, SE., MM | AC12: 895327038135 | AD12: setdakab.bdg@gmail.com | AE12: - | AF12: Harian
A13: 11 | B13: Layanan Transaksi | C13: Fungsi utama layanan transaksi di Kabupaten Bandung adalah untuk memudahkan masyarakat dalam memenuhi kewajiban pembayaran pajak daerah dan mendukung efisiensi pengelolaan pajak oleh pemerintah daerah. Layanan ini meliputi berbagai fasilitas dan sistem, seperti pengesahan STNK, pembayaran PKB, dan pemanfaatan teknologi untuk pelaporan data transaksi usaha secara online. | D13: Peraturan Bupati (Perbup) Kabupaten Bandung Nomor 22 Tahun 2018 tentang Implementasi Transaksi Non Tunai, yang telah beberapa kali diubah dengan Perbup Nomor 6 Tahun 2020 dan Perbup Nomor 15 Tahun 2020. | F13: AKUNTANSI DAN PELAPORAN KEUANGAN | G13: Instansi Pemerintah Lainnya | H13: Data Transaksi | I13: Data Rekening Koran | J13: Terbatas | K13: Tidak terdapat | L13: Lainnya | M13: IBC (Internet Banking Corporate) | N13: Pihak Ke 3 | O13: Pihak Ke 3 (Lisensi) | P13: Desktop | Q13: Aplikasi dari BJB | R13: Secara Online | S13: Transaksi | T13: 2019 | U13: Aktif | V13: Tidak | W13: Tidak Terintegrasi | X13: Tidak Terintegrasi | Y13: Tidak Terintegrasi | Z13: Bagian Perencanaan dan Keuangan | AA13: Setda | AB13: VERRYNOVYANDI SADIKIN, SE., MM | AC13: 895327038135 | AD13: setdakab.bdg@gmail.com | AE13: - | AF13: Harian
A14: 12 | B14: Layanan Penatausahaan Keuangan | C14: Fungsi layanan penatausahaan keuangan di Kabupaten Bandung adalah mencatat dan menyimpan semua transaksi penerimaan dan pengeluaran kas daerah secara akurat dan tertib untuk penyusunan laporan keuangan, pengendalian APBD, serta penyediaan data dan informasi keuangan yang dapat dipertanggungjawabkan. Penatausahaan ini mendukung efektivitas pengelolaan keuangan daerah dan memastikan transparansi serta akuntabilitas dalam penggunaan dana publik. | D14: Peraturan Bupati (Perbup) Kabupaten Bandung Nomor 48 Tahun 2025 tentang Perubahan Atas Peraturan Bupati Nomor 83 Tahun 2024 | F14: AKUNTANSI DAN PELAPORAN KEUANGAN | G14: Instansi Pemerintah Lainnya | H14: Data APBD | I14: Data APBD | J14: Tertutup | K14: Terdapat | L14: Lainnya | M14: SIPD | N14: Pusat | O14: Pusat | P14: Website | Q14: sipd.kemendagri.go.id | R14: Secara Online | S14: Transaksi | T14: 2021 | U14: Aktif | V14: Tidak | W14: Tidak Terintegrasi | X14: Tidak Terintegrasi | Y14: Tidak Terintegrasi | Z14: Bagian Perencanaan dan Keuangan | AA14: Setda | AB14: VERRYNOVYANDI SADIKIN, SE., MM | AC14: 895327038135 | AD14: setdakab.bdg@gmail.com | AE14: - | AF14: Harian
A15: 13 | B15: Layanan Tata Naskah Dinas | C15: Fungsi utama layanan Tata Naskah Dinas (TND) di Kabupaten Bandung adalah untuk menciptakan kelancaran komunikasi tertulis yang efektif dan efisien, memastikan keotentikan, keterpercayaan, kepastian, dan akuntabilitas informasi, serta mendukung terwujudnya tata kelola pemerintahan yang baik (good governance) melalui penerapan penggunaan naskah dinas secara elektronik. TND juga berfungsi sebagai sarana untuk mengatur jenis dan penyusunan naskah dinas, penggunaan lambang negara dan cap dinas, serta penggunaan bahasa Indonesia yang sesuai dalam komunikasi resmi. | D15: Peraturan Bupati (PERBUP) Nomor 82 Tahun 2024 tentang Pedoman Tata Naskah Dinas di Lingkungan Pemerintah Kabupaten Bandung. | F15: PENATAAN SISTEM TATA LAKSANA | G15: Instansi Pemerintah Lainnya | H15: Naskah Surat | I15: Surat yang dilegalisasi | J15: Terbatas | K15: Tidak terdapat | L15: Harian | M15: SULTAN (e-office) | N15: Diskominfo | O15: Kab. Bandung | P15: Website dan Mobile | Q15: https://sultan.bandungkab.go.id/ | R15: Secara Online | S15: Informasi | T15: 2025 | U15: Aktif | V15: Ya | W15: Terintegrasi dengan SIPPHADE, dll | X15: Web Service | Y15: Realtime | Z15: Semua Bagian | AA15: Setda | AB15: ALIPHIO DYAKSHA PUTRA, A.Md.Ak. | AC15: 8988005270 | AD15: setdakab.bdg@gmail.com | AE15: - | AF15: Harian
A16: 14 | B16: Layanan Perencanaan BMD | C16: Untuk mengidentifikasi kebutuhan aset, merencanakan pengadaan, pemanfaatan, pemeliharaan, dan pengelolaan aset agar sesuai dengan tugas dan fungsi SKPD, mendukung pelayanan publik, dan memastikan pengelolaan yang akuntabel dan transparan sesuai regulasi. Layanan ini bertujuan untuk menciptakan pengelolaan aset yang efisien dan efektif, mencegah pemborosan, serta mengoptimalkan penggunaan aset daerah untuk pembangunan. | D16: Undang-Undang Nomor 1 Tahun 2004 tentang Perbendaharaan Negara, Peraturan Pemerintah Nomor 27 Tahun 2014 tentang Pengelolaan BMD. | F16: PERENCANAAN PEMBANGUNAN | G16: Instansi Pemerintah Lainnya | H16: Data Kebutuhan Aset | I16: Pengadaan Aset | J16: Terbatas | K16: Tidak terdapat | L16: Tahunan | M16: SSH SBU | N16: OPD | O16: Kab. Bandung | P16: Website | Q16: sshsbu.e-planningbmd.id | R16: Secara Online | S16: Informasi | U16: Aktif | V16: Tidak | W16: Tidak Terintegrasi | X16: Tidak Terintegrasi | Y16: Tidak Terintegrasi | Z16: Bagian Perencanaan dan Keuangan | AA16: BKAD | AB16: YATI KURNIATI, SE., M.K.P. | AC16: 81321814674 | AD16: bagianprogramsetdakab.bandung@gmail.com | AE16: - | AF16: Tahunan
A17: 15 | B17: Layanan Statistik | C17: Indonesia Data Hub merupakan one stop collaboration platform yang bertujuan untuk meningkatkan literasi data dan value of statistics serta mendukung interoperabilitas data dan kolaborasi eksplorasi terhadap data. | D17: Undang-Undang Nomor 16 Tahun 1997 tentang Statistik sebagai dasar umum, serta Peraturan Presiden Nomor 86 Tahun 2007 dan Peraturan Kepala Badan Pusat Statistik (BPS) Nomor 78 Tahun 2020 yang mengatur pelayanan statistik terpadu di tingkat pusat. | F17: PENGELOLAAN DATA STATISTIK | G17: Instansi Pemerintah Lainnya | H17: Metadata dan Standar Data Statistik | I17: Metadata dan Standar Data Statistik | J17: Terbuka | K17: Tidak terdapat | L17: Lainnya | M17: INDAH | N17: Pusat | O17: Pusat | P17: Website | Q17: https://indah.bps.go.id/ | R17: Secara Online | S17: Informasi | T17: 2019 | U17: Aktif | V17: Ya | W17: Terintegrasi dengan Aplikasi Romantik | X17: Web Service | Y17: Realtime | Z17: Bagian Perencanaan dan Keuangan | AA17: Setda | AB17: DHANTI AURILIA PRATIWI, M.Stat | AC17: 81904085710 | AD17: setdakab.bdg@gmail.com | AE17: - | AF17: Tahunan
A18: 16 | B18: Layanan Informasi Pengawasan SAKIP, SPIP, MR | C18: Fungsinya adalah menyediakan data dan laporan pengawasan yang terintegrasi untuk mendukung perbaikan tata kelola, meningkatkan transparansi, mengurangi potensi penyimpangan, dan memperkuat pengambilan keputusan berbasis bukti dalam rangka mewujudkan pemerintahan yang efektif, efisien, dan akuntabel. | D18: Nomor 60 Tahun 2008 tentang Sistem Pengendalian Intern Pemerintah (SPIP), Peraturan Presiden (Perpres) Nomor 29 Tahun 2014 tentang Sistem Akuntabilitas Kinerja Instansi Pemerintah (SAKIP). | F18: PENINGKATAN KUALITAS PELAYANAN PUBLIK | G18: Instansi Pemerintah Lainnya | H18: Data Evidence SAKIP, SPIP, MR | I18: Nilai SAKIP dan MR | J18: Terbatas | K18: Tidak terdapat | L18: Tahunan | M18: SIMWAS | N18: Pihak Ke 3 | O18: Kab. Bandung | P18: Website | Q18: simwas.bandungkab.go.id | R18: Secara Online | S18: Transaksi | T18: 2022 | U18: Aktif | V18: Tidak | W18: Tidak Terintegrasi | X18: Tidak Terintegrasi | Y18: Tidak Terintegrasi | Z18: Bagian Perencanaan dan Keuangan | AA18: Setda, Inspektorat | AB18: DEBI RIANA S.STP., M.Si. | AC18: 8127392553 | AD18: setdakab.bdg@gmail.com | AE18: mungkin berkaitan dengan 27 | AF18: Tahunan
A19: 17 | B19: Layanan Informasi Data, Pengendalian, Evaluasi, dan Pelaporan | C19: Mencakup penyediaan dan pengelolaan data dan informasi pembangunan, pemantauan dan pengendalian pelaksanaan program/kegiatan, serta penyusunan laporan hasil evaluasi untuk mendukung perumusan kebijakan dan pengambilan keputusan. Layanan ini bertugas menganalisis data, mengoordinasikan evaluasi, dan menyusun pelaporan program pembangunan daerah. | D19: Undang-Undang Nomor 14 Tahun 2008 tentang Keterbukaan Informasi Publik, Undang-Undang Nomor 25 Tahun 2009 tentang Pelayanan Publik. | F19: PENINGKATAN KUALITAS REFORMASI BIROKRASI, PENGAWASAN, DAN AKUNTABILITAS KINERJA | G19: Instansi Pemerintah Lainnya | H19: Data Kinerja dan Realisasi Anggaran | I19: Data Capaian Kinerja dan Realisasi Anggaran | J19: Terbatas | K19: Tidak terdapat | L19: Lainnya | M19: SIDALMONEP | N19: OPD | O19: Kab. Bandung | P19: Website | Q19: sidalmonep.bandungkab.go.id/ | R19: Secara Online | S19: Informasi | T19: 2021 | U19: Aktif | V19: Tidak | W19: SIPD | X19: API | Y19: Realtime | Z19: Bagian Perencanaan dan Keuangan | AA19: Setda, Bapperida | AB19: YATI KURNIATI, SE., M.K.P. | AC19: 81321814674 | AD19: bagianprogramsetdakab.bandung@gmail.com | AE19: - | AF19: Tahunan
A20: 18 | B20: Layanan Pengelolaan Administrasi Kepegawaian | C20: mengelola administrasi, pengembangan, dan pelayanan pegawai secara efektif untuk mendukung kinerja Sekretariat Daerah. Fungsinya meliputi penyiapan bahan kebijakan, manajemen mutasi, kenaikan pangkat, pensiun, disiplin, hingga pengembangan kompetensi pegawai | D20: Undang-Undang Nomor 20 Tahun 2023 tentang Aparatur Sipil Negara | F20: PENATAAN SUMBER DAYA MANUSIA APARATUR | G20: Pegawai | H20: Data Kepegawaian | I20: Data Kepegawaian | J20: Terbatas | K20: Terdapat | L20: Harian | M20: SIMPEL BKPSDM | N20: Diskominfo | O20: Kab. Bandung | P20: Website | Q20: https://simpelbkpsdm.bandungkab.go.id/ | R20: Secara Online | S20: Informasi | U20: Aktif | V20: Ya | W20: Terintegrasi | X20: Database to Database | Y20: Realtime | Z20: Bagian Umum | AA20: BKPSDM | AB20: Iman Herman Sudrajat, S.IP. | AD20: bag_umum@bandungkab.go.id | AE20: 28 | AF20: Harian
A21: 19 | B21: Layanan Piagam Penghargaan Bupati Bandung | C21: Layanan Fasilitasi Piagam Penghargaan Bupati berupa administrasi penerbitan, penyiapan naskah, dan pendokumentasian piagam penghargaan Bupati Bandung | D21: Peraturan Bupati (PERBUP) Nomor 82 Tahun 2024 tentang Pedoman Tata Naskah Dinas di Lingkungan Pemerintah Kabupaten Bandung. | F21: PENINGKATAN KUALITAS PELAYANAN PUBLIK | G21: Instansi Pemerintah Lainnya | H21: Permohonan Piagam | I21: Naskah dan Dokumen Piagam | J21: Terbatas | K21: Tidak terdapat | L21: Lainnya | M21: Microsoft Excel | N21: OPD | O21: Kab. Bandung | P21: Desktop | Q21: - | R21: Secara Offline | S21: Informasi | U21: Aktif | V21: Tidak | W21: Tidak Terintegrasi | X21: Tidak Terintegrasi | Y21: Tidak Terintegrasi | Z21: Bagian Umum | AA21: Setda | AB21: Iman Herman Sudrajat, S.IP. | AD21: bag_umum@bandungkab.go.id | AE21: 28 | AF21: Harian
A22: 20 | B22: Layanan Informasi Akuntabilitas Kinerja | C22: Layanan Sistem Informasi Akuntabilitas Kinerja adalah sebuah sistem elektronik yang digunakan oleh instansi pemerintah untuk mengelola, mengukur, dan melaporkan kinerja secara terukur dan transparan. Sistem ini bertujuan untuk mewujudkan pemerintahan yang akuntabel, efektif, dan efisien, serta memberikan pertanggungjawaban atas penggunaan anggaran dan pencapaian tujuan organisasi kepada masyarakat. | D22: Peraturan Presiden Nomor 29 Tahun 2014 tentang Sistem Akuntabilitas Kinerja Instansi Pemerintah, serta peraturan pelaksanaannya seperti Peraturan Menteri Pendayagunaan Aparatur Negara dan Reformasi Birokrasi Nomor 88 Tahun 2021 tentang Evaluasi Akuntabilitas Kinerja Instansi Pemerintah | F22: PENINGKATAN KUALITAS REFORMASI BIROKRASI, PENGAWASAN, DAN AKUNTABILITAS KINERJA | G22: Instansi Pemerintah Lainnya | H22: Data Akuntabilitas Kinerja | I22: Data Akuntabilitas Kinerja | J22: Terbatas | K22: Tidak terdapat | L22: Tahunan | M22: SIAKANG | N22: OPD | O22: Kab. Bandung | P22: Website dan Mobile | Q22: siakang.bandungkab.go.id | R22: Secara Online | S22: Informasi | T22: 2023 | U22: Aktif | V22: Tidak | W22: Tidak Terintegrasi | X22: Tidak Terintegrasi | Y22: Tidak Terintegrasi | Z22: Bagian Organisasi | AA22: Setda | AB22: IRMA PURNAMA, S.STP, M.Tr.A.P | AC22: 85218888714 | AD22: setdakab.bdg@gmail.com
